<?xml version="1.0" ?>
<robot xmlns:xacro="http://www.ros.org/wiki/xacro">
<!-- =================================================================================== -->
<!-- |    This document was autogenerated by xacro from /home/darkhorse/ros2_ws/src/arduinobot_description/description/urdf/arduinobot_description.urdf.xacro | -->
<!-- |    EDITING THIS FILE BY HAND IS NOT RECOMMENDED                                 | -->
<!-- =================================================================================== -->
<!-- This URDF was automatically created by SolidWorks to URDF Exporter! Originally created by Stephen Brawner (brawner@gmail.com) 
     Commit Version: 1.6.0-4-g7f85cfe  Build Version: 1.6.7995.38578
     For more information, please see http://wiki.ros.org/sw_urdf_exporter -->
  <xacro:arg name = "is_ignition" default = "true"/>
  <link name = "world"/>

  <joint name = "base_joint" type = "fixed">
    <parent link = "world"/>
    <child link = "base_link"/>
    <origin rpy = "0 0 0" xyz = "0.0 0.0 0.0"/>
  </joint>
<link
    name="base_link">
    <inertial>
      <origin
        xyz="0.00067074 0.026079 -0.00067074"
        rpy="0 0 0" />
      <mass
        value="1.6594" />
      <inertia
        ixx="0.0046976"
        ixy="4.6829E-06"
        ixz="-7.3002E-05"
        iyy="0.0081457"
        iyz="-4.6829E-06"
        izz="0.0046976" />
    </inertial>
    <visual>
      <origin
        xyz="0 0 0"
        rpy="0 0 0" />
      <geometry>
        <mesh
          filename="package://arduinobot_description/meshes/base_link.STL" />
      </geometry>
      <material
        name="">
        <color
          rgba="0.79216 0.81961 0.93333 1" />
      </material>
    </visual>
    <collision>
      <origin
        xyz="0 0 0"
        rpy="0 0 0" />
      <geometry>
        <mesh
          filename="package://arduinobot_description/meshes/base_link.STL" />
      </geometry>
    </collision>
  </link>
  <link
    name="link_1">
    <inertial>
      <origin
        xyz="-0.042602 0.086543 0.0034922"
        rpy="0 0 0" />
      <mass
        value="1.5863" />
      <inertia
        ixx="0.0073712"
        ixy="0.0051171"
        ixz="0.00039749"
        iyy="0.0083314"
        iyz="-0.0003937"
        izz="0.01317" />
    </inertial>
    <visual>
      <origin
        xyz="0 0 0"
        rpy="0 0 0" />
      <geometry>
        <mesh
          filename="package://arduinobot_description/meshes/link_1.STL" />
      </geometry>
      <material
        name="">
        <color
          rgba="0.69412 0.098039 0.098039 1" />
      </material>
    </visual>
    <collision>
      <origin
        xyz="0 0 0"
        rpy="0 0 0" />
      <geometry>
        <mesh
          filename="package://arduinobot_description/meshes/link_1.STL" />
      </geometry>
    </collision>
  </link>
  <joint
    name="joint_1"
    type="revolute">
    <origin
      xyz="0 0 0.05"
      rpy="1.5708 0 0.45791" />
    <parent
      link="base_link" />
    <child
      link="link_1" />
    <axis
      xyz="0 1 0" />
    <limit
      lower="0"
      upper="3.142"
      effort="200"
      velocity="3" />
  </joint>
  <link
    name="link_2">
    <inertial>
      <origin
        xyz="-0.14503 0.031735 0.008829"
        rpy="0 0 0" />
      <mass
        value="1.1214" />
      <inertia
        ixx="0.00077647"
        ixy="0.00010994"
        ixz="0.00027965"
        iyy="0.021115"
        iyz="1.5086E-06"
        izz="0.020765" />
    </inertial>
    <visual>
      <origin
        xyz="0 0 0"
        rpy="0 0 0" />
      <geometry>
        <mesh
          filename="package://arduinobot_description/meshes/link_2.STL" />
      </geometry>
      <material
        name="">
        <color
          rgba="0.69412 0.098039 0.098039 1" />
      </material>
    </visual>
    <collision>
      <origin
        xyz="0 0 0"
        rpy="0 0 0" />
      <geometry>
        <mesh
          filename="package://arduinobot_description/meshes/link_2.STL" />
      </geometry>
    </collision>
  </link>
  <joint
    name="joint_2"
    type="revolute">
    <origin
      xyz="-0.1461 0.18286 0"
      rpy="-1.5708 0 -1.8957" />
    <parent
      link="link_1" />
    <child
      link="link_2" />
    <axis
      xyz="0 -1 0" />
    <limit
      lower="-1.57"
      upper="1.57"
      effort="200"
      velocity="3" />
  </joint>
  <link
    name="link_3">
    <inertial>
      <origin
        xyz="0.044368 0.055668 -0.021756"
        rpy="0 0 0" />
      <mass
        value="1.0046" />
      <inertia
        ixx="0.0013582"
        ixy="-0.0004625"
        ixz="3.3743E-05"
        iyy="0.0041005"
        iyz="4.7084E-05"
        izz="0.0047697" />
    </inertial>
    <visual>
      <origin
        xyz="0 0 0"
        rpy="0 0 0" />
      <geometry>
        <mesh
          filename="package://arduinobot_description/meshes/link_3.STL" />
      </geometry>
      <material
        name="">
        <color
          rgba="0.79216 0.81961 0.93333 1" />
      </material>
    </visual>
    <collision>
      <origin
        xyz="0 0 0"
        rpy="0 0 0" />
      <geometry>
        <mesh
          filename="package://arduinobot_description/meshes/link_3.STL" />
      </geometry>
    </collision>
  </link>
  <joint
    name="joint_3"
    type="revolute">
    <origin
      xyz="-0.35 0 0"
      rpy="-1.5708 1.2391 0" />
    <parent
      link="link_2" />
    <child
      link="link_3" />
    <axis
      xyz="0 0 1" />
    <limit
      lower="0"
      upper="3.142"
      effort="200"
      velocity="3" />
  </joint>
  <link
    name="link_4">
    <inertial>
      <origin
        xyz="0.06401 -1.6292E-07 -7.6483E-08"
        rpy="0 0 0" />
      <mass
        value="0.44798" />
      <inertia
        ixx="0.00045822"
        ixy="-3.9267E-10"
        ixz="1.192E-08"
        iyy="0.0012345"
        iyz="5.9882E-11"
        izz="0.0010823" />
    </inertial>
    <visual>
      <origin
        xyz="0 0 0"
        rpy="0 0 0" />
      <geometry>
        <mesh
          filename="package://arduinobot_description/meshes/link_4.STL" />
      </geometry>
      <material
        name="">
        <color
          rgba="0.79216 0.81961 0.93333 1" />
      </material>
    </visual>
    <collision>
      <origin
        xyz="0 0 0"
        rpy="0 0 0" />
      <geometry>
        <mesh
          filename="package://arduinobot_description/meshes/link_4.STL" />
      </geometry>
    </collision>
  </link>
  <joint
    name="joint_4"
    type="revolute">
    <origin
      xyz="0.30339 0.067122 -0.0225"
      rpy="0.11661 0 0" />
    <parent
      link="link_3" />
    <child
      link="link_4" />
    <axis
      xyz="1 0 0" />
    <limit
      lower="0"
      upper="3.142"
      effort="200"
      velocity="3" />
  </joint>
  <link
    name="link_5">
    <inertial>
      <origin
        xyz="1.1102E-16 -0.054303 -4.1633E-17"
        rpy="0 0 0" />
      <mass
        value="0.38604" />
      <inertia
        ixx="0.00044952"
        ixy="1.5924E-19"
        ixz="1.3553E-20"
        iyy="0.00031694"
        iyz="7.4539E-20"
        izz="0.00044603" />
    </inertial>
    <visual>
      <origin
        xyz="0 0 0"
        rpy="0 0 0" />
      <geometry>
        <mesh
          filename="package://arduinobot_description/meshes/link_5.STL" />
      </geometry>
      <material
        name="">
        <color
          rgba="0.79216 0.81961 0.93333 1" />
      </material>
    </visual>
    <collision>
      <origin
        xyz="0 0 0"
        rpy="0 0 0" />
      <geometry>
        <mesh
          filename="package://arduinobot_description/meshes/link_5.STL" />
      </geometry>
    </collision>
  </link>
  <joint
    name="joint_5"
    type="revolute">
    <origin
      xyz="0.10501 0 0"
      rpy="0 0 0.040471" />
    <parent
      link="link_4" />
    <child
      link="link_5" />
    <axis
      xyz="0 0 -1" />
    <limit
      lower="0"
      upper="3.142"
      effort="200"
      velocity="3" />
  </joint>
  <link
    name="link_6">
    <inertial>
      <origin
        xyz="1.1102E-16 -0.03103 5.5511E-17"
        rpy="0 0 0" />
      <mass
        value="0.18088" />
      <inertia
        ixx="0.00011376"
        ixy="-1.1435E-20"
        ixz="-1.6941E-21"
        iyy="0.00011418"
        iyz="-7.6233E-21"
        izz="0.00010947" />
    </inertial>
    <visual>
      <origin
        xyz="0 0 0"
        rpy="0 0 0" />
      <geometry>
        <mesh
          filename="package://arduinobot_description/meshes/link_6.STL" />
      </geometry>
      <material
        name="">
        <color
          rgba="0.79216 0.81961 0.93333 1" />
      </material>
    </visual>
    <collision>
      <origin
        xyz="0 0 0"
        rpy="0 0 0" />
      <geometry>
        <mesh
          filename="package://arduinobot_description/meshes/link_6.STL" />
      </geometry>
    </collision>
  </link>
  <joint
    name="joint_6"
    type="revolute">
    <origin
      xyz="0 -0.085863 0"
      rpy="0 -0.21729 0" />
    <parent
      link="link_5" />
    <child
      link="link_6" />
    <axis
      xyz="0 -1 0" />
    <limit
      lower="0"
      upper="3.142"
      effort="200"
      velocity="3" />
  </joint>
  <link
    name="gripper_1">
    <inertial>
      <origin
        xyz="0.015647 6.5254E-05 0.051476"
        rpy="0 0 0" />
      <mass
        value="0.05463" />
      <inertia
        ixx="6.4686E-05"
        ixy="-5.9695E-08"
        ixz="-1.3165E-05"
        iyy="6.8871E-05"
        iyz="-1.262E-07"
        izz="1.0445E-05" />
    </inertial>
    <visual>
      <origin
        xyz="0 0 0"
        rpy="0 0 0" />
      <geometry>
        <mesh
          filename="package://arduinobot_description/meshes/gripper_1.STL" />
      </geometry>
      <material
        name="">
        <color
          rgba="0.2 0.2 0.2 1" />
      </material>
    </visual>
    <collision>
      <origin
        xyz="0 0 0"
        rpy="0 0 0" />
      <geometry>
        <mesh
          filename="package://arduinobot_description/meshes/gripper_1.STL" />
      </geometry>
    </collision>
  </link>
  <joint
    name="joint_7"
    type="revolute">
    <origin
      xyz="0 -0.06071 -0.03614"
      rpy="-3.1416 -1.4875 -1.5708" />
    <parent
      link="link_6" />
    <child
      link="gripper_1" />
    <axis
      xyz="0 -1 0" />
    <limit
      lower="0"
      upper="1.57"
      effort="200"
      velocity="3" />
  </joint>
  <link
    name="gripper_2">
    <inertial>
      <origin
        xyz="0.015647 6.5254E-05 0.051476"
        rpy="0 0 0" />
      <mass
        value="0.05463" />
      <inertia
        ixx="6.4686E-05"
        ixy="-5.9695E-08"
        ixz="-1.3165E-05"
        iyy="6.8871E-05"
        iyz="-1.262E-07"
        izz="1.0445E-05" />
    </inertial>
    <visual>
      <origin
        xyz="0 0 0"
        rpy="0 0 0" />
      <geometry>
        <mesh
          filename="package://arduinobot_description/meshes/gripper_2.STL" />
      </geometry>
      <material
        name="">
        <color
          rgba="0.2 0.2 0.2 1" />
      </material>
    </visual>
    <collision>
      <origin
        xyz="0 0 0"
        rpy="0 0 0" />
      <geometry>
        <mesh
          filename="package://arduinobot_description/meshes/gripper_2.STL" />
      </geometry>
    </collision>
  </link>
  <joint
    name="joint_8"
    type="revolute">
    <origin
      xyz="0 -0.06071 0.03614"
      rpy="0 1.1954 -1.5708" />
    <parent
      link="link_6" />
    <child
      link="gripper_2" />
    <axis
      xyz="0 1 0" />
    <limit
      lower="0"
      upper="1.57"
      effort="200"
      velocity="3" />
    <mimic joint = "joint_7" multiplier = "-1"/>
  </joint>
</robot>
